Workbook
Name sample_figures: 'Example Balance Sheet'!$B$2:$E$28
Name Current_Liabilities: 'Balance Sheet'!$A$40
Name Inventory: 'Balance Sheet'!$B$21
Name What_is_a_profit_and_loss_statement?: 'Example Profit & Loss'!$A$2:$A$3
Name _Toc250359346: 'Example Profit & Loss'!$B$3
Name Other_current_assets: 'Balance Sheet'!$B$27
Name Working_Capital_Funds____________________________________________Current_Assets_Less_Current_Liabilities: 'Balance Sheet'!$A$67
Name Leverage_Ratio__Total_Liabilities___Total_Assets: 'Balance Sheet'!$A$68
Name Balance_Sheet_Ratios: 'Balance Sheet'!$A$63
Name Debtors: 'Balance Sheet'!$B$13
Name Sample_profit_and_loss: 'Example Profit & Loss'!$E$3:$H$34
Name Instructions: 'Balance Sheet'!$A$2:$A$8
Name Net_Assets: 'Balance Sheet'!$A$57
Name Instructions: 'Detailed P&L'!$A$2:$A$4
Name Total_Shareholders_Funds__Equity: 'Balance Sheet'!$A$62
Name Cashflows_from_Operations: 'Cashflow Statement'!$A$2:$C$13
Name Current_Ratio__Current_Assets___Current_Liabilities: 'Balance Sheet'!$A$65
Name Instructions: 'Summary P&L'!$A$1:$A$4
Name Financing_Activities: 'Cashflow Statement'!$A$22:$C$30
Name For_the_Year_Ending: 'Cashflow Statement'!$D$3:$E$4
Name Investing_Activities: 'Cashflow Statement'!$A$14:$C$21
Name Long_Term_Liabilities: 'Balance Sheet'!$A$51
Name Cash_on_hand: 'Balance Sheet'!$B$12
Name Profit_and_Loss_Ratios: 'Summary P&L'!$A$25:$N$32
Name Quick_Ratio___Current_Assets_less_inventory_____Current_Liabilities_less_bank_overdraft: 'Balance Sheet'!$A$66
Name Short_term_Investments: 'Balance Sheet'!$B$26
Name Tip_Hint: 'Example Profit & Loss'!$A$36
Name Date_and_starting_cash: 'Cashflow Statement'!$D$2:$E$4
Name Jan_13: 'Detailed P&L'!$B$5

Sheet Example Profit & Loss
A1: Example profit and loss statement
A2: What is a profit and loss statement? The profit and loss statement is a summary of a business’s income and expenses over a specific period. It should be prepared at regular intervals (usually monthly and at financial year end) to show the results of operations for a given period. Calculating the cost of goods sold varies depending on whether the business is retail, wholesale, manufacturing, or a service business. In retailing and wholesaling, computing the cost of goods sold during the reporting period involves beginning and ending inventories. This, of course, includes purchases made during the reporting period. In manufacturing, it involves finished-goods inventories, plus raw materials inventories, goods-in-process inventories, direct labour, and direct factory overhead costs. In the case of a service business, the revenue is being derived from the activities of individuals rather than the sale of a product and hence the calculation of cost of goods sold is a smaller task due to the low-level use of materials required to earn the income.
A3: The image below shows how profit and loss are calculated. | E3: Joe’s Motorbike Tyres
E4: Profit and Loss Statement
E5: For the Period ended Year One
E6: Income
F7: Sales | G7: 52000 | H7: ( 1,000 tyres @ $ 52 each)
F8: Total Sales | G8: 52000
E9: Cost of Goods Sold
F10: Opening Stock | G10: $ -
F11: Stock Purchases | G11: 34320
F12: Less Closing Stock | G12: 3120
E13: Total Cost of Goods Sold(COGS) | G13: 31200 | H13: ( See note below)
E14: Gross Profit | G14: 20800
E15: Expenses
F16: Advertising | G16: 500
F17: Bank Service Charges | G17: 120
F18: Insurance | G18: 500
F19: Payroll | G19: 13000
F20: Professional Fees (Legal, Accounting) | G20: 200
F21: Utilities & Telephone | G21: 800
F22: Other: Computer Software | G22: 480
F23: Expenses total | G23: 15600
E24: Net Profit before Tax | G24: 5200
E26: Note; Cost of Goods Sold calculation:
E27: Towards the end of the year, Joe manages to purchase 100 more tyres on credit from his supplier for an order in the new year. This leaves him with $3,120 of stock on hand at the end of the year.
E28: Joe’s Cost of Goods Calculation
E29: Opening Stock Nil
E30: Add Stock Purchased during the year | G30: 34320 | H30: (1100 tyres @ 31.20 each)
E31: Equals Stock available to sell | G31: 34320
E32: Less Stock on hand at end of year | G32: 3120 | H32: (100 tyres @ 31.20 each)
E33: Cost of Goods Sold | G33: 31200
E34: Where a business is a service business, that is, you are selling services not goods or products, then the profit and loss statement will generally not have a cost of goods sold calculation. In some instances, where labour costs can be directly attributed to sales, then you may consider including these costs as a cost of goods (services) sold.
A36: Tip: Regularly produce profit and loss information (monthly) and compare against previous month’s activities to ensure your profit expectations are being met. Hint: Only those businesses that have goods (products) to sell will use the calculation of cost of goods sold

Sheet Detailed P&L
A1: Profit and Loss Statement
A2: Instructions
A3: Give careful thought to the headings.
A4: Expand the sales income and expenses area if your business has distinct categories (e.g. a restaurant may have food sales and beverage sales listed separately and cost of sales for each also separated).
A5: Month | B5: 43466 | C5: =DATE(YEAR(B5),MONTH(B5)+1,1) -> 43497 | D5: =DATE(YEAR(B5),MONTH(B5)+2,1) -> 43525 | E5: =DATE(YEAR(B5),MONTH(B5)+3,1) -> 43556 | F5: =DATE(YEAR(B5),MONTH(B5)+4,1) -> 43586 | G5: =DATE(YEAR(B5),MONTH(B5)+5,1) -> 43617 | H5: =DATE(YEAR(B5),MONTH(B5)+6,1) -> 43647 | I5: =DATE(YEAR(B5),MONTH(B5)+7,1) -> 43678 | J5: =DATE(YEAR(B5),MONTH(B5)+8,1) -> 43709 | K5: =DATE(YEAR(B5),MONTH(B5)+9,1) -> 43739 | L5: =DATE(YEAR(B5),MONTH(B5)+10,1) -> 43770 | M5: =DATE(YEAR(B5),MONTH(B5)+11,1) -> 43800
A6: Income
A7: Sales
A8: Sale of goods/services | B8: 0 | C8: 0 | D8: 0 | E8: 0 | F8: 0 | G8: 0 | H8: 0 | I8: 0 | J8: 0 | K8: 0 | L8: 0 | M8: 0
A9: Sundry Income (e.g. Commission earned, frachise fees etc.) | B9: 0 | C9: 0 | D9: 0 | E9: 0 | F9: 0 | G9: 0 | H9: 0 | I9: 0 | J9: 0 | K9: 0 | L9: 0 | M9: 0
A10: Etc. | B10: 0 | C10: 0 | D10: 0 | E10: 0 | F10: 0 | G10: 0 | H10: 0 | I10: 0 | J10: 0 | K10: 0 | L10: 0 | M10: 0
A11: Total Sales | B11: =SUM(B7:B10) -> 0 | C11: =SUM(C7:C10) -> 0 | D11: =SUM(D7:D10) -> 0 | E11: =SUM(E7:E10) -> 0 | F11: =SUM(F7:F10) -> 0 | G11: =SUM(G7:G10) -> 0 | H11: =SUM(H7:H10) -> 0 | I11: =SUM(I7:I10) -> 0 | ... M11: =SUM(M7:M10) -> 0
A12: Less Discounts/Commissions
A13: Sales Discounts given | B13: 0 | C13: 0 | D13: 0 | E13: 0 | F13: 0 | G13: 0 | H13: 0 | I13: 0 | J13: 0 | K13: 0 | L13: 0 | M13: 0
A14: Sales Commissions paid | B14: 0 | C14: 0 | D14: 0 | E14: 0 | F14: 0 | G14: 0 | H14: 0 | I14: 0 | J14: 0 | K14: 0 | L14: 0 | M14: 0
A15: Total Discounts/ Commissions | B15: =SUM(B13:B14) -> 0 | C15: =SUM(C13:C14) -> 0 | D15: =SUM(D13:D14) -> 0 | E15: =SUM(E13:E14) -> 0 | F15: =SUM(F13:F14) -> 0 | G15: =SUM(G13:G14) -> 0 | H15: =SUM(H13:H14) -> 0 | I15: =SUM(I13:I14) -> 0 | ... M15: =SUM(M13:M14) -> 0
A16: Total Net Income | B16: =B11-B15 -> 0 | C16: =C11-C15 -> 0 | D16: =D11-D15 -> 0 | E16: =E11-E15 -> 0 | F16: =F11-F15 -> 0 | G16: =G11-G15 -> 0 | H16: =H11-H15 -> 0 | I16: =I11-I15 -> 0 | ... M16: =M11-M15 -> 0
A17: Cost of Sales
A18: Opening Stock | B18: 0 | C18: 0 | D18: 0 | E18: 0 | F18: 0 | G18: 0 | H18: 0 | I18: 0 | J18: 0 | K18: 0 | L18: 0 | M18: 0
A19: Stock Purchased | B19: 0 | C19: 0 | D19: 0 | E19: 0 | F19: 0 | G19: 0 | H19: 0 | I19: 0 | J19: 0 | K19: 0 | L19: 0 | M19: 0
B20: =SUM(B18:B19) -> 0 | C20: =SUM(C18:C19) -> 0 | D20: =SUM(D18:D19) -> 0 | E20: =SUM(E18:E19) -> 0 | F20: =SUM(F18:F19) -> 0 | G20: =SUM(G18:G19) -> 0 | H20: =SUM(H18:H19) -> 0 | I20: =SUM(I18:I19) -> 0 | ... M20: =SUM(M18:M19) -> 0
A21: Less Closing Stock | B21: 0 | C21: 0 | D21: 0 | E21: 0 | F21: 0 | G21: 0 | H21: 0 | I21: 0 | J21: 0 | K21: 0 | L21: 0 | M21: 0
A22: Total Cost of Sales | B22: =B20-B21 -> 0 | C22: =C20-C21 -> 0 | D22: =D20-D21 -> 0 | E22: =E20-E21 -> 0 | F22: =F20-F21 -> 0 | G22: =G20-G21 -> 0 | H22: =H20-H21 -> 0 | I22: =I20-I21 -> 0 | ... M22: =M20-M21 -> 0
A24: Gross Profit | B24: =B16-B22 -> 0 | C24: =C16-C22 -> 0 | D24: =D16-D22 -> 0 | E24: =E16-E22 -> 0 | F24: =F16-F22 -> 0 | G24: =G16-G22 -> 0 | H24: =H16-H22 -> 0 | I24: =I16-I22 -> 0 | ... M24: =M16-M22 -> 0
A25: Expenses
A26: General & Administrative
A27: Bank charges | B27: 0 | C27: 0 | D27: 0 | E27: 0 | F27: 0 | G27: 0 | H27: 0 | I27: 0 | J27: 0 | K27: 0 | L27: 0 | M27: 0
A28: Credit card commission | B28: 0 | C28: 0 | D28: 0 | E28: 0 | F28: 0 | G28: 0 | H28: 0 | I28: 0 | J28: 0 | K28: 0 | L28: 0 | M28: 0
A29: Consultant fees | B29: 0 | C29: 0 | D29: 0 | E29: 0 | F29: 0 | G29: 0 | H29: 0 | I29: 0 | J29: 0 | K29: 0 | L29: 0 | M29: 0
A30: Office Supplies | B30: 0 | C30: 0 | D30: 0 | E30: 0 | F30: 0 | G30: 0 | H30: 0 | I30: 0 | J30: 0 | K30: 0 | L30: 0 | M30: 0
A31: License fees | B31: 0 | C31: 0 | D31: 0 | E31: 0 | F31: 0 | G31: 0 | H31: 0 | I31: 0 | J31: 0 | K31: 0 | L31: 0 | M31: 0
A32: Business insurance | B32: 0 | C32: 0 | D32: 0 | E32: 0 | F32: 0 | G32: 0 | H32: 0 | I32: 0 | J32: 0 | K32: 0 | L32: 0 | M32: 0
A33: Etc. | B33: 0 | C33: 0 | D33: 0 | E33: 0 | F33: 0 | G33: 0 | H33: 0 | I33: 0 | J33: 0 | K33: 0 | L33: 0 | M33: 0
A34: Total General & Administrative | B34: =SUM(B27:B33) -> 0 | C34: =SUM(C27:C33) -> 0 | D34: =SUM(D27:D33) -> 0 | E34: =SUM(E27:E33) -> 0 | F34: =SUM(F27:F33) -> 0 | G34: =SUM(G27:G33) -> 0 | H34: =SUM(H27:H33) -> 0 | I34: =SUM(I27:I33) -> 0 | ... M34: =SUM(M27:M33) -> 0
A35: Marketing & Promotional
A36: Advertising | B36: 0 | C36: 0 | D36: 0 | E36: 0 | F36: 0 | G36: 0 | H36: 0 | I36: 0 | J36: 0 | K36: 0 | L36: 0 | M36: 0
A37: Promotion - General | B37: 0 | C37: 0 | D37: 0 | E37: 0 | F37: 0 | G37: 0 | H37: 0 | I37: 0 | J37: 0 | K37: 0 | L37: 0 | M37: 0
A38: Promotion - Other | B38: 0 | C38: 0 | D38: 0 | E38: 0 | F38: 0 | G38: 0 | H38: 0 | I38: 0 | J38: 0 | K38: 0 | L38: 0 | M38: 0
A39: Etc. | B39: 0 | C39: 0 | D39: 0 | E39: 0 | F39: 0 | G39: 0 | H39: 0 | I39: 0 | J39: 0 | K39: 0 | L39: 0 | M39: 0
A40: Total Marketing & Promotional | B40: =SUM(B36:B39) -> 0 | C40: =SUM(C36:C39) -> 0 | D40: =SUM(D36:D39) -> 0 | E40: =SUM(E36:E39) -> 0 | F40: =SUM(F36:F39) -> 0 | G40: =SUM(G36:G39) -> 0 | H40: =SUM(H36:H39) -> 0 | I40: =SUM(I36:I39) -> 0 | ... M40: =SUM(M36:M39) -> 0
A41: Operating Expenses
...

Sheet Summary P&L
A1: Instructions
A2: Give careful thought to the headings.
A3: Expand the sales income and expenses area if your business has distinct categories
A4: (e.g. a restaurant may have food sales and beverage sales listed separately and cost of sales for each also separated).
A5: Profit & Loss Statement
A6: Month | C6: 43466 | D6: =DATE(YEAR(C6),MONTH(C6)+1,1) -> 43497 | E6: =DATE(YEAR(C6),MONTH(C6)+2,1) -> 43525 | F6: =DATE(YEAR(C6),MONTH(C6)+3,1) -> 43556 | G6: =DATE(YEAR(C6),MONTH(C6)+4,1) -> 43586 | H6: =DATE(YEAR(C6),MONTH(C6)+5,1) -> 43617 | I6: =DATE(YEAR(C6),MONTH(C6)+6,1) -> 43647 | J6: =DATE(YEAR(C6),MONTH(C6)+7,1) -> 43678 | K6: =DATE(YEAR(C6),MONTH(C6)+8,1) -> 43709 | L6: =DATE(YEAR(C6),MONTH(C6)+9,1) -> 43739 | M6: =DATE(YEAR(C6),MONTH(C6)+10,1) -> 43770 | N6: =DATE(YEAR(C6),MONTH(C6)+11,1) -> 43800
A7: Income
B8: Total Sales | C8: ='Detailed P&L'!B11 -> 0 | D8: ='Detailed P&L'!C11 -> 0 | E8: ='Detailed P&L'!D11 -> 0 | F8: ='Detailed P&L'!E11 -> 0 | G8: ='Detailed P&L'!F11 -> 0 | H8: ='Detailed P&L'!G11 -> 0 | I8: ='Detailed P&L'!H11 -> 0 | J8: ='Detailed P&L'!I11 -> 0 | ... N8: ='Detailed P&L'!M11 -> 0
B9: Less Total Disc/Comm | C9: ='Detailed P&L'!B15 -> 0 | D9: ='Detailed P&L'!C15 -> 0 | E9: ='Detailed P&L'!D15 -> 0 | F9: ='Detailed P&L'!E15 -> 0 | G9: ='Detailed P&L'!F15 -> 0 | H9: ='Detailed P&L'!G15 -> 0 | I9: ='Detailed P&L'!H15 -> 0 | J9: ='Detailed P&L'!I15 -> 0 | ... N9: ='Detailed P&L'!M15 -> 0
B10: Total Net Income | C10: ='Detailed P&L'!B16 -> 0 | D10: ='Detailed P&L'!C16 -> 0 | E10: ='Detailed P&L'!D16 -> 0 | F10: ='Detailed P&L'!E16 -> 0 | G10: ='Detailed P&L'!F16 -> 0 | H10: ='Detailed P&L'!G16 -> 0 | I10: ='Detailed P&L'!H16 -> 0 | J10: ='Detailed P&L'!I16 -> 0 | ... N10: ='Detailed P&L'!M16 -> 0
B11: Less Total Cost of Gooods Sold | C11: ='Detailed P&L'!B22 -> 0 | D11: ='Detailed P&L'!C22 -> 0 | E11: ='Detailed P&L'!D22 -> 0 | F11: ='Detailed P&L'!E22 -> 0 | G11: ='Detailed P&L'!F22 -> 0 | H11: ='Detailed P&L'!G22 -> 0 | I11: ='Detailed P&L'!H22 -> 0 | J11: ='Detailed P&L'!I22 -> 0 | ... N11: ='Detailed P&L'!M22 -> 0
B12: Gross Profit | C12: ='Detailed P&L'!B24 -> 0 | D12: ='Detailed P&L'!C24 -> 0 | E12: ='Detailed P&L'!D24 -> 0 | F12: ='Detailed P&L'!E24 -> 0 | G12: ='Detailed P&L'!F24 -> 0 | H12: ='Detailed P&L'!G24 -> 0 | I12: ='Detailed P&L'!H24 -> 0 | J12: ='Detailed P&L'!I24 -> 0 | ... N12: ='Detailed P&L'!M24 -> 0
B13: Expenses
B14: General & Administrative | C14: ='Detailed P&L'!B34 -> 0 | D14: ='Detailed P&L'!C34 -> 0 | E14: ='Detailed P&L'!D34 -> 0 | F14: ='Detailed P&L'!E34 -> 0 | G14: ='Detailed P&L'!F34 -> 0 | H14: ='Detailed P&L'!G34 -> 0 | I14: ='Detailed P&L'!H34 -> 0 | J14: ='Detailed P&L'!I34 -> 0 | ... N14: ='Detailed P&L'!M34 -> 0
B15: Marketing & Promotional | C15: ='Detailed P&L'!B40 -> 0 | D15: ='Detailed P&L'!C40 -> 0 | E15: ='Detailed P&L'!D40 -> 0 | F15: ='Detailed P&L'!E40 -> 0 | G15: ='Detailed P&L'!F40 -> 0 | H15: ='Detailed P&L'!G40 -> 0 | I15: ='Detailed P&L'!H40 -> 0 | J15: ='Detailed P&L'!I40 -> 0 | ... N15: ='Detailed P&L'!M40 -> 0
B16: Operating Expenses | C16: ='Detailed P&L'!B51 -> 0 | D16: ='Detailed P&L'!C51 -> 0 | E16: ='Detailed P&L'!D51 -> 0 | F16: ='Detailed P&L'!E51 -> 0 | G16: ='Detailed P&L'!F51 -> 0 | H16: ='Detailed P&L'!G51 -> 0 | I16: ='Detailed P&L'!H51 -> 0 | J16: ='Detailed P&L'!I51 -> 0 | ... N16: ='Detailed P&L'!M51 -> 0
B17: Motor Vehicle Expenses | C17: ='Detailed P&L'!B58 -> 0 | D17: ='Detailed P&L'!C58 -> 0 | E17: ='Detailed P&L'!D58 -> 0 | F17: ='Detailed P&L'!E58 -> 0 | G17: ='Detailed P&L'!F58 -> 0 | H17: ='Detailed P&L'!G58 -> 0 | I17: ='Detailed P&L'!H58 -> 0 | J17: ='Detailed P&L'!I58 -> 0 | ... N17: ='Detailed P&L'!M58 -> 0
B18: Website Expenses | C18: ='Detailed P&L'!B63 -> 0 | D18: ='Detailed P&L'!C63 -> 0 | E18: ='Detailed P&L'!D63 -> 0 | F18: ='Detailed P&L'!E63 -> 0 | G18: ='Detailed P&L'!F63 -> 0 | H18: ='Detailed P&L'!G63 -> 0 | I18: ='Detailed P&L'!H63 -> 0 | J18: ='Detailed P&L'!I63 -> 0 | ... N18: ='Detailed P&L'!M63 -> 0
B19: Total Employment Expenses | C19: ='Detailed P&L'!B80 -> 0 | D19: ='Detailed P&L'!C80 -> 0 | E19: ='Detailed P&L'!D80 -> 0 | F19: ='Detailed P&L'!E80 -> 0 | G19: ='Detailed P&L'!F80 -> 0 | H19: ='Detailed P&L'!G80 -> 0 | I19: ='Detailed P&L'!H80 -> 0 | J19: ='Detailed P&L'!I80 -> 0 | ... N19: ='Detailed P&L'!M80 -> 0
B20: Occupancy Costs | C20: ='Detailed P&L'!B91 -> 0 | D20: ='Detailed P&L'!C91 -> 0 | E20: ='Detailed P&L'!D91 -> 0 | F20: ='Detailed P&L'!E91 -> 0 | G20: ='Detailed P&L'!F91 -> 0 | H20: ='Detailed P&L'!G91 -> 0 | I20: ='Detailed P&L'!H91 -> 0 | J20: ='Detailed P&L'!I91 -> 0 | ... N20: ='Detailed P&L'!M91 -> 0
B21: Other Expenses | C21: ='Detailed P&L'!B100 -> 0 | D21: ='Detailed P&L'!C100 -> 0 | E21: ='Detailed P&L'!D100 -> 0 | F21: ='Detailed P&L'!E100 -> 0 | G21: ='Detailed P&L'!F100 -> 0 | H21: ='Detailed P&L'!G100 -> 0 | I21: ='Detailed P&L'!H100 -> 0 | J21: ='Detailed P&L'!I100 -> 0 | ... N21: ='Detailed P&L'!M100 -> 0
A22: Total Expenses | C22: ='Detailed P&L'!B101 -> 0 | D22: ='Detailed P&L'!C101 -> 0 | E22: ='Detailed P&L'!D101 -> 0 | F22: ='Detailed P&L'!E101 -> 0 | G22: ='Detailed P&L'!F101 -> 0 | H22: ='Detailed P&L'!G101 -> 0 | I22: ='Detailed P&L'!H101 -> 0 | J22: ='Detailed P&L'!I101 -> 0 | ... N22: ='Detailed P&L'!M101 -> 0
A23: Monthly Net Profit / (Loss) | C23: ='Detailed P&L'!B102 -> 0 | D23: ='Detailed P&L'!C102 -> 0 | E23: ='Detailed P&L'!D102 -> 0 | F23: ='Detailed P&L'!E102 -> 0 | G23: ='Detailed P&L'!F102 -> 0 | H23: ='Detailed P&L'!G102 -> 0 | I23: ='Detailed P&L'!H102 -> 0 | J23: ='Detailed P&L'!I102 -> 0 | ... N23: ='Detailed P&L'!M102 -> 0
A24: Total Year to Date Net Profit / (Loss) | C24: ='Detailed P&L'!B103 -> 0 | D24: ='Detailed P&L'!C103 -> 0 | E24: ='Detailed P&L'!D103 -> 0 | F24: ='Detailed P&L'!E103 -> 0 | G24: ='Detailed P&L'!F103 -> 0 | H24: ='Detailed P&L'!G103 -> 0 | I24: ='Detailed P&L'!H103 -> 0 | J24: ='Detailed P&L'!I103 -> 0 | ... N24: ='Detailed P&L'!M103 -> 0
A25: Profit and Loss Ratios
A27: Gross Margin (Gross Profit / Net Income) | C27: =C12/C10 -> #DIV/0! | D27: =D12/D10 -> #DIV/0! | E27: =E12/E10 -> #DIV/0! | F27: =F12/F10 -> #DIV/0! | G27: =G12/G10 -> #DIV/0! | H27: =H12/H10 -> #DIV/0! | I27: =I12/I10 -> #DIV/0! | J27: =J12/J10 -> #DIV/0! | ... N27: =N12/N10 -> #DIV/0!
A28: Net Margin (Net Profit / Net Income) | C28: =C23/C10 -> #DIV/0! | D28: =D23/D10 -> #DIV/0! | E28: =E23/E10 -> #DIV/0! | F28: =F23/F10 -> #DIV/0! | G28: =G23/G10 -> #DIV/0! | H28: =H23/H10 -> #DIV/0! | I28: =I23/I10 -> #DIV/0! | J28: =J23/J10 -> #DIV/0! | ... N28: =N23/N10 -> #DIV/0!
A30: Mark Up ((Net Income Less Cost of Goods Sold) / (Cost of Goods Sold)) x 100 | C30: =(C10-C11)/C11 -> #DIV/0! | D30: =(D10-D11)/D11 -> #DIV/0! | E30: =(E10-E11)/E11 -> #DIV/0! | F30: =(F10-F11)/F11 -> #DIV/0! | G30: =(G10-G11)/G11 -> #DIV/0! | H30: =(H10-H11)/H11 -> #DIV/0! | I30: =(I10-I11)/I11 -> #DIV/0! | J30: =(J10-J11)/J11 -> #DIV/0! | ... N30: =(N10-N11)/N11 -> #DIV/0!
A32: Break Even ( Expenses/((1-(Cost of Goods Sold/ Net Income)) | C32: =C22/(1-(C11/C10)) -> #DIV/0! | D32: =D22/(1-(D11/D10)) -> #DIV/0! | E32: =E22/(1-(E11/E10)) -> #DIV/0! | F32: =F22/(1-(F11/F10)) -> #DIV/0! | G32: =G22/(1-(G11/G10)) -> #DIV/0! | H32: =H22/(1-(H11/H10)) -> #DIV/0! | I32: =I22/(1-(I11/I10)) -> #DIV/0! | J32: =J22/(1-(J11/J10)) -> #DIV/0! | ... N32: =N22/(1-(N11/N10)) -> #DIV/0!

Sheet Example Balance Sheet
A1: Example Balance Sheet
B2: Joe’s Motorbike Tyres
B3: Balance Sheet
B4: As at end of Year One
B5: Current Assets
B6: Cash | C6: 5100
B7: Debtors | C7: 18000
B8: Stock | C8: 3120
B9: Total Current Assets | D9: 26220
B10: Non-current Assets
B11: Computer | C11: 5500
B12: Store Fit Out | C12: 8100
B13: Office Equipment | C13: 15000
B15: Total Non-current Assets | D15: 28600
B16: Total Assets | D16: 54820
B17: Current Liabilities
B18: Credit Card | C18: 5500
B19: Creditors | C19: 4120
B20: Total Current Liabilities | D20: 9620
B21: Non-current Liabilities
B22: Total Non-current Liabilities
B23: Total Liabilities | D23: 9620
B24: Net Assets | E24: 45200
B25: Shareholders’ Equity
B26: Owners’ Funds | D26: 40000
B27: Current Year Profit | D27: 5200
B28: Total Shareholders' Equity | E28: 45200

Sheet Balance Sheet
A1: Balance Sheet
A2: Instructions
A3: The Balance Sheet shows the financial position of the business as at a point in time
A4: Prepare a balance sheet for the start of the business, six months later and then at the end of the first year.
A5: Draw the information from the Profit & Loss Statement and the Cash Flow Statement.
A6: A Balance Sheet brings together the results from the Profit & Loss Statement and the Cash Flow Statement.
A7: (Download from the Business Victoria website at http://www.business.vic.gov.au.)
A8: Fill in the figures below, expanding or reducing the assets, liabilities and shareholders equity areas.
A9: Month | D9: Start of Business | E9: ='Summary P&L'!H6 -> 43617 | F9: ='Summary P&L'!N6 -> 43800
A10: Assets
A11: Current Assets
B12: Cash on hand | D12: 0 | E12: 0 | F12: 0
B13: Debtors | D13: 0 | E13: 0 | F13: 0
B14: Prepaid Expenses
C15: General | D15: 0 | E15: 0 | F15: 0
C16: Rates | D16: 0 | E16: 0 | F16: 0
C17: Workcover | D17: 0 | E17: 0 | F17: 0
C18: Insurance | D18: 0 | E18: 0 | F18: 0
C19: Etc. | D19: 0 | E19: 0 | F19: 0
C20: Total Prepaid expenses | D20: =SUM(D15:D19) -> 0 | E20: =SUM(E15:E19) -> 0 | F20: =SUM(F15:F19) -> 0
B21: Inventory
C22: Tyres | D22: 0 | E22: 0 | F22: 0
C23: Parts | D23: 0 | E23: 0 | F23: 0
C24: Etc. | D24: 0 | E24: 0 | F24: 0
C25: Total Inventory | D25: =SUM(D22:D24) -> 0 | E25: =SUM(E22:E24) -> 0 | F25: =SUM(F22:F24) -> 0
B26: Short term Investments | D26: 0 | E26: 0 | F26: 0
B27: Other current assets | D27: 0 | E27: 0 | F27: 0
A28: Total Current Assets | D28: =D12+D13+D20+D25+D26+D27 -> 0 | E28: =E12+E13+E20+E25+E26+E27 -> 0 | F28: =F12+F13+F20+F25+F26+F27 -> 0
A29: Fixed Assets
B30: Computer | D30: 0 | E30: 0 | F30: 0
B31: Store Fit Out | D31: 0 | E31: 0 | F31: 0
B32: Office Equipment | D32: 0 | E32: 0 | F32: 0
B33: Leasehold | D33: 0 | E33: 0 | F33: 0
B34: Buildings & improvements | D34: 0 | E34: 0 | F34: 0
B35: Furniture & Fixtures | D35: 0 | E35: 0 | F35: 0
B36: Etc. | D36: 0 | E36: 0 | F36: 0
A37: Total Fixed Assets | D37: =SUM(D33:D36) -> 0 | E37: =SUM(E33:E36) -> 0 | F37: =SUM(F33:F36) -> 0
A38: Total Assets | D38: =D28+D37 -> 0 | E38: =E28+E37 -> 0 | F38: =F28+F37 -> 0
A39: Liabilities
A40: Current Liabilities
...

Sheet Example Cashflow Statement
A1: Example cashflow statement

Sheet Cashflow Statement
A1: Cash Flow Statement
A2: Cashflows from Operations | D2: Date and starting cash
A3: Cash receipts from customers | D3: For the Year Ending
A4: (enter positive amounts) | B4: Cash Sales | C4: 0 | D4: Cash at Beginning of Year
B5: Cash collected from customers (debtors) | C5: 0
A6: Funding from Creditors
B7: Stock purchased, not yet paid | C7: 0
A8: Cash paid for
A9: (enter negative amounts) | B9: Total Expenses | C9: 0
B10: Inventory (stock)purchases | C10: 0
A11: Funding to Debtors
B12: Sales made not yet collected | C12: 0
A13: Net Cash Flow from Operations | C13: =SUM(C4:C12) -> 0
A14: Investing Activities
A15: Cash receipts from
A16: (enter positive amounts) | B16: Sale of property and equipment | C16: 0
B17: Matured Investments | C17: 0
A18: Cash paid for
A19: (enter negative amounts) | B19: Purchase of property and equipment | C19: 0
B20: Purchase of investments | C20: 0
A21: Net Cash Flow from Investing Activities | C21: =SUM(C15:C20) -> 0
A22: Financing Activities
A23: Cash receipts from
A24: (enter positive amounts) | B24: Increase in short term debt | C24: 0
B25: Increase in long term debt | C25: 0
B26: Increase in equity (proceeds from owners) | C26: 0
A27: Cash paid for
A28: (enter negative amounts) | B28: Repayment of loans | C28: 0
B29: Dividends | C29: 0
A30: Net Cash Flow from Financing Activities | C30: =SUM(C24:C29) -> 0
A31: Net Increase in Cash | C31: =C13+C21+C30 -> 0
B32: Cash at End of Year | C32: =E4+C31 -> 0
